occurred date & time: 2023-06-08 16:03:57 INFO     
file name: _internal.py
line number: 224 
error: [31m[1mWARNING: This is a development server. Do not use it in a production deployment. Use a production WSGI server instead.[0m
 * Running on http://127.0.0.1:5000
occurred date & time: 2023-06-08 16:03:57 INFO     
file name: _internal.py
line number: 224 
error: [33mPress CTRL+C to quit[0m
occurred date & time: 2023-06-08 16:04:02 INFO     
file name: _internal.py
line number: 224 
error: 127.0.0.1 - - [08/Jun/2023 16:04:02] "GET / HTTP/1.1" 200 -
occurred date & time: 2023-06-08 16:04:02 INFO     
file name: _internal.py
line number: 224 
error: 127.0.0.1 - - [08/Jun/2023 16:04:02] "[36mGET /static/input_page.css HTTP/1.1[0m" 304 -
occurred date & time: 2023-06-08 16:04:02 INFO     
file name: _internal.py
line number: 224 
error: 127.0.0.1 - - [08/Jun/2023 16:04:02] "[36mGET /static/js/input_page.js HTTP/1.1[0m" 304 -
occurred date & time: 2023-06-08 16:04:02 INFO     
file name: _internal.py
line number: 224 
error: 127.0.0.1 - - [08/Jun/2023 16:04:02] "[36mGET /static/filimo_logo.png HTTP/1.1[0m" 304 -
occurred date & time: 2023-06-08 16:04:02 INFO     
file name: _internal.py
line number: 224 
error: 127.0.0.1 - - [08/Jun/2023 16:04:02] "[36mGET /static/scrap.gif HTTP/1.1[0m" 304 -
occurred date & time: 2023-06-08 16:04:27 ERROR    
file name: app.py
line number: 1744 
error: Exception on /submit [POST]
Traceback (most recent call last):
  File "/home/salehmh/.local/lib/python3.10/site-packages/flask/app.py", line 2528, in wsgi_app
    response = self.full_dispatch_request()
  File "/home/salehmh/.local/lib/python3.10/site-packages/flask/app.py", line 1825, in full_dispatch_request
    rv = self.handle_user_exception(e)
  File "/home/salehmh/.local/lib/python3.10/site-packages/flask/app.py", line 1823, in full_dispatch_request
    rv = self.dispatch_request()
  File "/home/salehmh/.local/lib/python3.10/site-packages/flask/app.py", line 1799, in dispatch_request
    return self.ensure_sync(self.view_functions[rule.endpoint])(**view_args)
  File "/home/salehmh/Documents/Saoshyant/Filimo-Data-Collector/user_interface.py", line 27, in submit
    instance = filimo.Filimo(i)
  File "/home/salehmh/Documents/Saoshyant/Filimo-Data-Collector/filimo.py", line 43, in __init__
    driver.get(self.movie_links)
  File "/home/salehmh/.local/lib/python3.10/site-packages/selenium/webdriver/remote/webdriver.py", line 449, in get
    self.execute(Command.GET, {"url": url})
  File "/home/salehmh/.local/lib/python3.10/site-packages/selenium/webdriver/remote/webdriver.py", line 440, in execute
    self.error_handler.check_response(response)
  File "/home/salehmh/.local/lib/python3.10/site-packages/selenium/webdriver/remote/errorhandler.py", line 245, in check_response
    raise exception_class(message, screen, stacktrace)
selenium.common.exceptions.TimeoutException: Message: TimedPromise timed out after 15000 ms
Stacktrace:
RemoteError@chrome://remote/content/shared/RemoteError.sys.mjs:8:8
WebDriverError@chrome://remote/content/shared/webdriver/Errors.sys.mjs:182:5
TimeoutError@chrome://remote/content/shared/webdriver/Errors.sys.mjs:492:5
bail@chrome://remote/content/marionette/sync.sys.mjs:211:19

occurred date & time: 2023-06-08 16:04:27 INFO     
file name: _internal.py
line number: 224 
error: 127.0.0.1 - - [08/Jun/2023 16:04:27] "[35m[1mPOST /submit HTTP/1.1[0m" 500 -
